<?xml version="0.0" ?>
<robot name="">
	<link name="link0_1">
		<inertial>
			<origin rpy="0.00000 -0.00000 0.00000" xyz="0.00000 0.00000 0.00000"/>
			<mass value="0.01"/>
      		<inertia ixx="0.2125" ixy="-0.005" ixz="0.0225" iyy="0.205" iyz="0.045" izz="0.0125"/>
		</inertial>
	</link>
	<link name="link0_2">
		<inertial>
			<origin rpy="0.00000 -0.00000 0.00000" xyz="0.00000 0.00000 0.00000"/>
			<mass value="0.01"/>
      		<inertia ixx="0.2125" ixy="-0.005" ixz="0.0225" iyy="0.205" iyz="0.045" izz="0.0125"/>
		</inertial>
	</link>
	<link name="link0_3">
		<inertial>
			<origin rpy="0.00000 -0.00000 0.00000" xyz="0.00000 0.00000 0.00000"/>
			<mass value="0.01"/>
      		<inertia ixx="0.2125" ixy="-0.005" ixz="0.0225" iyy="0.205" iyz="0.045" izz="0.0125"/>
		</inertial>
	</link>
	<link name="torso">
		<inertial>
			<origin rpy="0.00000 -0.00000 0.00000" xyz="0.00000 0.00000 0.00000"/>
			<mass value="9.45733"/>
			<inertia ixx="0.08894" ixy="0" ixz="0" iyy="1.46688" iyz="0" izz="1.39128"/>
		</inertial>
		<collision>
			<origin rpy="0.00000 1.57080 -0.00000" xyz="0.00000 0.00000 0.00000"/>
			<geometry>
				<capsule length="1.00000" radius="0.04600"/>
			</geometry>
		</collision>
		<collision>
			<origin rpy="0.00000 0.87000 0.00000" xyz="0.60000 0.00000 0.10000"/>
			<geometry>
				<capsule length="0.30000" radius="0.04600"/>
			</geometry>
		</collision>
	</link>
	<link name="bthigh">
		<inertial>
			<origin rpy="3.14159 0.65841 3.14159" xyz="0.10000 0.00000 -0.130000"/>
			<mass value="2.33553"/>
			<inertia ixx="0.02665" ixy="0" ixz="0" iyy="0.04329" iyz="0" izz="0.01993"/>
		</inertial>
		<collision>
			<origin rpy="3.14159 0.65841 3.14159" xyz="0.10000 0.00000 -0.13000"/>
			<geometry>
				<capsule length="0.29000" radius="0.04600"/>
			</geometry>
		</collision>
	</link>
	<link name="bshin">
		<inertial>
			<origin rpy="3.14159 -1.11159 3.14159" xyz="-0.14000 0.00000 -0.07000"/>
			<mass value="2.40200"/>
			<inertia ixx="0.01483" ixy="0" ixz="0" iyy="0.04393" iyz="0" izz="0.03248"/>
		</inertial>
		<collision>
			<origin rpy="3.14159 -1.11159 3.14159" xyz="-0.14000 0.00000 -0.07000"/>
			<geometry>
				<capsule length="0.30000" radius="0.04600"/>
			</geometry>
		</collision>
	</link>
	<link name="bfoot">
		<inertial>
			<origin rpy="0.00000 -0.27000 0.00000"  xyz="0.03000 0.00000 -0.09700"/>
			<mass value="1.5"/>
			<inertia ixx="0.07928" ixy="0" ixz="0" iyy="0.09446" iyz="0" izz="0.02929"/>
		</inertial>
		<collision>
			<origin rpy="0.00000 -0.27000 0.00000" xyz="0.03000 0.00000 -0.09700"/>
			<geometry>
				<capsule length="0.18800" radius="0.04600"/>
			</geometry>
		</collision>
	</link>
	<link name="fthigh">
		<inertial>
			<origin rpy="0.00000 0.52000 0.00000" xyz="-0.07000 0.00000 -0.12000"/>
			<mass value="2.17598"/>
			<inertia ixx="0.02457" ixy="0" ixz="0" iyy="0.03508" iyz="0" izz="0.01358"/>
		</inertial>
		<collision>
			<origin rpy="0.00000 0.52000 0.00000" xyz="-0.07000 0.00000 -0.12000"/>
			<geometry>
				<capsule length="0.26600" radius="0.04600"/>
			</geometry>
		</collision>

	</link>
	<link name="fshin">
		<inertial>
			<origin rpy="0.00000 -0.60000 0.00000" xyz="0.06500 0.00000 -0.09000"/>
			<mass value="1.81701"/>
			<inertia ixx="0.01517" ixy="0" ixz="0" iyy="0.02317" iyz="0" izz="0.01056"/>
		</inertial>
		<collision>
			<origin rpy="0.00000 -0.60000 0.00000" xyz="0.06500 0.00000 -0.09000"/>
			<geometry>
				<capsule length="0.21200" radius="0.04600"/>
			</geometry>
		</collision>

	</link>
	<link name="ffoot">
		<inertial>
			<origin rpy="0.00000 -0.60000 0.00000" xyz="0.04500 0.00000 -0.07000"/>
			<mass value="1.5"/>
			<inertia ixx="0.05643" ixy="0" ixz="0" iyy="0.08506" iyz="0" izz="0.04274"/>
		</inertial>
		<collision>
			<origin rpy="0.00000 -0.60000 0.00000" xyz="0.04500 0.00000 -0.07000"/>
			<geometry>
				<capsule length="0.14000" radius="0.04600"/>
			</geometry>
		</collision>

	</link>
	<joint name="ignorex" type="prismatic">
		<parent link="link0_1"/>
		<child link="link0_2"/>
		<limit effort="0.0" lower="1" upper="-1" velocity="1000"/>		
		<origin rpy="0.00000 -0.00000 0.00000" xyz="0.00000 0.00000 0.70000"/>
		<axis xyz="1.00000 0.00000 0.00000"/>
	</joint>
	<joint name="ignorez" type="prismatic">
		<parent link="link0_2"/>
		<child link="link0_3"/>
		<limit effort="0.0" lower="1" upper="-1" velocity="1000"/>	
		<origin rpy="0.00000 -0.00000 0.00000" xyz="0.00000 0.00000 0.00000"/>
		<axis xyz="0.00000 0.00000 1.00000"/>
	</joint>
	<joint name="ignorey" type="continuous">
		<parent link="link0_3"/>
		<child link="torso"/>
		<origin rpy="0.00000 -0.00000 0.00000" xyz="0.00000 0.00000 0.00000"/>
		<axis xyz="0.00000 1.00000 0.00000"/>
	</joint>
	<joint name="bthigh" type="revolute">
		<parent link="torso"/>
		<child link="bthigh"/>
		<limit lower="-0.52" upper="1.05"/>	
		<origin rpy="0.00000 -0.00000 0.00000" xyz="-0.50000 0.00000 0.00000"/>
		<axis xyz="0.00000 1.00000 0.00000"/>
		<dynamics damping="0" friction="0.0"/>
	</joint>
	<joint name="bshin" type="revolute">
		<parent link="bthigh"/>
		<child link="bshin"/>
		<limit lower="-0.87" upper="0.87"/>	
		<origin rpy="0.00000 -0.00000 0.00000" xyz="0.16000 0.00000 -0.25000"/>
		<axis xyz="0.00000 1.00000 0.00000"/>
		<dynamics damping="0" friction="0.0"/>
	</joint>
	<joint name="bfoot" type="revolute">
		<parent link="bshin"/>
		<child link="bfoot"/>
		<limit lower="-0.87" upper="0.87"/>	
		<origin rpy="0.00000 -0.00000 0.00000" xyz="-0.28000 0.00000 -0.14000"/>
		<axis xyz="0.00000 1.00000 0.00000"/>
		<dynamics damping="0" friction="0.0"/>
	</joint>
	<joint name="fthigh" type="revolute">
		<parent link="torso"/>
		<child link="fthigh"/>
		<limit lower="-1" upper="0.3"/>	
		<origin rpy="0.00000 -0.00000 0.00000" xyz="0.50000 0.00000 0.00000"/>
		<axis xyz="0.00000 1.00000 0.00000"/>
		<dynamics damping="0" friction="0.0"/>
	</joint>
	<joint name="fshin" type="revolute">
		<parent link="fthigh"/>
		<child link="fshin"/>
		<limit lower="-1.22" upper="0.87"/>	
		<origin rpy="0.00000 -0.00000 0.00000" xyz="-0.14000 0.00000 -0.24000"/>
		<axis xyz="0.00000 1.00000 0.00000"/>
		<dynamics damping="0" friction="0.0"/>
	</joint>
	<joint name="ffoot" type="revolute">
		<parent link="fshin"/>
		<child link="ffoot"/>
		<limit lower="-0.48" upper="0.48"/>	
		<origin rpy="0.00000 -0.00000 0.00000" xyz="0.13000 0.00000 -0.18000"/>
		<axis xyz="0.00000 1.00000 0.00000"/>
		<dynamics damping="0" friction="0.0"/>
	</joint>
</robot>
